\chapter{Gestione degli errori}
Si ottiene grazie al blocco try...catch che una volta trovato un errore in try genera un eccezione che viene catturata in catch che viene eseguito. finally, a differenza
del catch viene sempre eseguito, sia che sia stata generata un eccezione che non sia stata generata.